2020-10-09 14:36:26,232 INFO: Microblog startup [in /Users/filipporivolta/Desktop/Sites/Apps/microblogging/app/__init__.py:38]
2020-10-09 14:36:31,646 ERROR: Exception on /edit-profile [POST] [in /Users/filipporivolta/Desktop/Sites/Apps/microblogging/venv/lib/python3.8/site-packages/flask/app.py:1891]
Traceback (most recent call last):
  File "/Users/filipporivolta/Desktop/Sites/Apps/microblogging/venv/lib/python3.8/site-packages/sqlalchemy/engine/base.py", line 1276, in _execute_context
    self.dialect.do_execute(
  File "/Users/filipporivolta/Desktop/Sites/Apps/microblogging/venv/lib/python3.8/site-packages/sqlalchemy/engine/default.py", line 593, in do_execute
    cursor.execute(statement, parameters)
sqlite3.IntegrityError: UNIQUE constraint failed: user.username

The above exception was the direct cause of the following exception:

Traceback (most recent call last):
  File "/Users/filipporivolta/Desktop/Sites/Apps/microblogging/venv/lib/python3.8/site-packages/flask/app.py", line 2447, in wsgi_app
    response = self.full_dispatch_request()
  File "/Users/filipporivolta/Desktop/Sites/Apps/microblogging/venv/lib/python3.8/site-packages/flask/app.py", line 1952, in full_dispatch_request
    rv = self.handle_user_exception(e)
  File "/Users/filipporivolta/Desktop/Sites/Apps/microblogging/venv/lib/python3.8/site-packages/flask/app.py", line 1821, in handle_user_exception
    reraise(exc_type, exc_value, tb)
  File "/Users/filipporivolta/Desktop/Sites/Apps/microblogging/venv/lib/python3.8/site-packages/flask/_compat.py", line 39, in reraise
    raise value
  File "/Users/filipporivolta/Desktop/Sites/Apps/microblogging/venv/lib/python3.8/site-packages/flask/app.py", line 1950, in full_dispatch_request
    rv = self.dispatch_request()
  File "/Users/filipporivolta/Desktop/Sites/Apps/microblogging/venv/lib/python3.8/site-packages/flask/app.py", line 1936, in dispatch_request
    return self.view_functions[rule.endpoint](**req.view_args)
  File "/Users/filipporivolta/Desktop/Sites/Apps/microblogging/venv/lib/python3.8/site-packages/flask_login/utils.py", line 272, in decorated_view
    return func(*args, **kwargs)
  File "/Users/filipporivolta/Desktop/Sites/Apps/microblogging/app/routes.py", line 88, in edit_profile
    db.session.commit()
  File "/Users/filipporivolta/Desktop/Sites/Apps/microblogging/venv/lib/python3.8/site-packages/sqlalchemy/orm/scoping.py", line 163, in do
    return getattr(self.registry(), name)(*args, **kwargs)
  File "/Users/filipporivolta/Desktop/Sites/Apps/microblogging/venv/lib/python3.8/site-packages/sqlalchemy/orm/session.py", line 1042, in commit
    self.transaction.commit()
  File "/Users/filipporivolta/Desktop/Sites/Apps/microblogging/venv/lib/python3.8/site-packages/sqlalchemy/orm/session.py", line 504, in commit
    self._prepare_impl()
  File "/Users/filipporivolta/Desktop/Sites/Apps/microblogging/venv/lib/python3.8/site-packages/sqlalchemy/orm/session.py", line 483, in _prepare_impl
    self.session.flush()
  File "/Users/filipporivolta/Desktop/Sites/Apps/microblogging/venv/lib/python3.8/site-packages/sqlalchemy/orm/session.py", line 2523, in flush
    self._flush(objects)
  File "/Users/filipporivolta/Desktop/Sites/Apps/microblogging/venv/lib/python3.8/site-packages/sqlalchemy/orm/session.py", line 2664, in _flush
    transaction.rollback(_capture_exception=True)
  File "/Users/filipporivolta/Desktop/Sites/Apps/microblogging/venv/lib/python3.8/site-packages/sqlalchemy/util/langhelpers.py", line 68, in __exit__
    compat.raise_(
  File "/Users/filipporivolta/Desktop/Sites/Apps/microblogging/venv/lib/python3.8/site-packages/sqlalchemy/util/compat.py", line 182, in raise_
    raise exception
  File "/Users/filipporivolta/Desktop/Sites/Apps/microblogging/venv/lib/python3.8/site-packages/sqlalchemy/orm/session.py", line 2624, in _flush
    flush_context.execute()
  File "/Users/filipporivolta/Desktop/Sites/Apps/microblogging/venv/lib/python3.8/site-packages/sqlalchemy/orm/unitofwork.py", line 422, in execute
    rec.execute(self)
  File "/Users/filipporivolta/Desktop/Sites/Apps/microblogging/venv/lib/python3.8/site-packages/sqlalchemy/orm/unitofwork.py", line 586, in execute
    persistence.save_obj(
  File "/Users/filipporivolta/Desktop/Sites/Apps/microblogging/venv/lib/python3.8/site-packages/sqlalchemy/orm/persistence.py", line 230, in save_obj
    _emit_update_statements(
  File "/Users/filipporivolta/Desktop/Sites/Apps/microblogging/venv/lib/python3.8/site-packages/sqlalchemy/orm/persistence.py", line 994, in _emit_update_statements
    c = cached_connections[connection].execute(
  File "/Users/filipporivolta/Desktop/Sites/Apps/microblogging/venv/lib/python3.8/site-packages/sqlalchemy/engine/base.py", line 1011, in execute
    return meth(self, multiparams, params)
  File "/Users/filipporivolta/Desktop/Sites/Apps/microblogging/venv/lib/python3.8/site-packages/sqlalchemy/sql/elements.py", line 298, in _execute_on_connection
    return connection._execute_clauseelement(self, multiparams, params)
  File "/Users/filipporivolta/Desktop/Sites/Apps/microblogging/venv/lib/python3.8/site-packages/sqlalchemy/engine/base.py", line 1124, in _execute_clauseelement
    ret = self._execute_context(
  File "/Users/filipporivolta/Desktop/Sites/Apps/microblogging/venv/lib/python3.8/site-packages/sqlalchemy/engine/base.py", line 1316, in _execute_context
    self._handle_dbapi_exception(
  File "/Users/filipporivolta/Desktop/Sites/Apps/microblogging/venv/lib/python3.8/site-packages/sqlalchemy/engine/base.py", line 1510, in _handle_dbapi_exception
    util.raise_(
  File "/Users/filipporivolta/Desktop/Sites/Apps/microblogging/venv/lib/python3.8/site-packages/sqlalchemy/util/compat.py", line 182, in raise_
    raise exception
  File "/Users/filipporivolta/Desktop/Sites/Apps/microblogging/venv/lib/python3.8/site-packages/sqlalchemy/engine/base.py", line 1276, in _execute_context
    self.dialect.do_execute(
  File "/Users/filipporivolta/Desktop/Sites/Apps/microblogging/venv/lib/python3.8/site-packages/sqlalchemy/engine/default.py", line 593, in do_execute
    cursor.execute(statement, parameters)
sqlalchemy.exc.IntegrityError: (sqlite3.IntegrityError) UNIQUE constraint failed: user.username
[SQL: UPDATE user SET username=?, about_me=? WHERE user.id = ?]
[parameters: ('filippo', 'fasdfasd', 2)]
(Background on this error at: http://sqlalche.me/e/13/gkpj)
2020-10-09 14:57:36,679 INFO: Microblog startup [in /Users/filipporivolta/Desktop/Sites/Apps/microblogging/app/__init__.py:38]
2020-10-09 14:57:40,903 ERROR: Exception on /edit-profile [POST] [in /Users/filipporivolta/Desktop/Sites/Apps/microblogging/venv/lib/python3.8/site-packages/flask/app.py:1891]
Traceback (most recent call last):
  File "/Users/filipporivolta/Desktop/Sites/Apps/microblogging/venv/lib/python3.8/site-packages/flask/app.py", line 2447, in wsgi_app
    response = self.full_dispatch_request()
  File "/Users/filipporivolta/Desktop/Sites/Apps/microblogging/venv/lib/python3.8/site-packages/flask/app.py", line 1953, in full_dispatch_request
    return self.finalize_request(rv)
  File "/Users/filipporivolta/Desktop/Sites/Apps/microblogging/venv/lib/python3.8/site-packages/flask/app.py", line 1968, in finalize_request
    response = self.make_response(rv)
  File "/Users/filipporivolta/Desktop/Sites/Apps/microblogging/venv/lib/python3.8/site-packages/flask/app.py", line 2097, in make_response
    raise TypeError(
TypeError: The view function did not return a valid response. The function either returned None or ended without a return statement.
2020-10-09 14:57:51,619 ERROR: Exception on /edit-profile [POST] [in /Users/filipporivolta/Desktop/Sites/Apps/microblogging/venv/lib/python3.8/site-packages/flask/app.py:1891]
Traceback (most recent call last):
  File "/Users/filipporivolta/Desktop/Sites/Apps/microblogging/venv/lib/python3.8/site-packages/flask/app.py", line 2447, in wsgi_app
    response = self.full_dispatch_request()
  File "/Users/filipporivolta/Desktop/Sites/Apps/microblogging/venv/lib/python3.8/site-packages/flask/app.py", line 1953, in full_dispatch_request
    return self.finalize_request(rv)
  File "/Users/filipporivolta/Desktop/Sites/Apps/microblogging/venv/lib/python3.8/site-packages/flask/app.py", line 1968, in finalize_request
    response = self.make_response(rv)
  File "/Users/filipporivolta/Desktop/Sites/Apps/microblogging/venv/lib/python3.8/site-packages/flask/app.py", line 2097, in make_response
    raise TypeError(
TypeError: The view function did not return a valid response. The function either returned None or ended without a return statement.
2020-10-09 14:59:18,246 INFO: Microblog startup [in /Users/filipporivolta/Desktop/Sites/Apps/microblogging/app/__init__.py:38]
2020-10-09 14:59:30,049 ERROR: Exception on /edit-profile [POST] [in /Users/filipporivolta/Desktop/Sites/Apps/microblogging/venv/lib/python3.8/site-packages/flask/app.py:1891]
Traceback (most recent call last):
  File "/Users/filipporivolta/Desktop/Sites/Apps/microblogging/venv/lib/python3.8/site-packages/flask/app.py", line 2447, in wsgi_app
    response = self.full_dispatch_request()
  File "/Users/filipporivolta/Desktop/Sites/Apps/microblogging/venv/lib/python3.8/site-packages/flask/app.py", line 1953, in full_dispatch_request
    return self.finalize_request(rv)
  File "/Users/filipporivolta/Desktop/Sites/Apps/microblogging/venv/lib/python3.8/site-packages/flask/app.py", line 1968, in finalize_request
    response = self.make_response(rv)
  File "/Users/filipporivolta/Desktop/Sites/Apps/microblogging/venv/lib/python3.8/site-packages/flask/app.py", line 2097, in make_response
    raise TypeError(
TypeError: The view function did not return a valid response. The function either returned None or ended without a return statement.
